[2023-02-20T21:00:08.136+0000] {taskinstance.py:1083} INFO - Dependencies all met for <TaskInstance: ifgoiano_site_dag.get_data scheduled__2023-02-19T21:00:00+00:00 [queued]>
[2023-02-20T21:00:08.158+0000] {taskinstance.py:1083} INFO - Dependencies all met for <TaskInstance: ifgoiano_site_dag.get_data scheduled__2023-02-19T21:00:00+00:00 [queued]>
[2023-02-20T21:00:08.159+0000] {taskinstance.py:1279} INFO - 
--------------------------------------------------------------------------------
[2023-02-20T21:00:08.160+0000] {taskinstance.py:1280} INFO - Starting attempt 1 of 6
[2023-02-20T21:00:08.160+0000] {taskinstance.py:1281} INFO - 
--------------------------------------------------------------------------------
[2023-02-20T21:00:08.199+0000] {taskinstance.py:1300} INFO - Executing <Task(PythonOperator): get_data> on 2023-02-19 21:00:00+00:00
[2023-02-20T21:00:08.221+0000] {standard_task_runner.py:55} INFO - Started process 3362 to run task
[2023-02-20T21:00:08.271+0000] {standard_task_runner.py:82} INFO - Running: ['***', 'tasks', 'run', 'ifgoiano_site_dag', 'get_data', 'scheduled__2023-02-19T21:00:00+00:00', '--job-id', '18', '--raw', '--subdir', 'DAGS_FOLDER/ifgoiano_site_dag.py', '--cfg-path', '/tmp/tmp1z22yvul']
[2023-02-20T21:00:08.272+0000] {standard_task_runner.py:83} INFO - Job 18: Subtask get_data
[2023-02-20T21:00:08.605+0000] {task_command.py:388} INFO - Running <TaskInstance: ifgoiano_site_dag.get_data scheduled__2023-02-19T21:00:00+00:00 [running]> on host f5b6b7502b7e
[2023-02-20T21:00:08.847+0000] {taskinstance.py:1509} INFO - Exporting the following env vars:
AIRFLOW_CTX_DAG_OWNER=Rafael
AIRFLOW_CTX_DAG_ID=ifgoiano_site_dag
AIRFLOW_CTX_TASK_ID=get_data
AIRFLOW_CTX_EXECUTION_DATE=2023-02-19T21:00:00+00:00
AIRFLOW_CTX_TRY_NUMBER=1
AIRFLOW_CTX_DAG_RUN_ID=scheduled__2023-02-19T21:00:00+00:00
[2023-02-20T21:00:36.225+0000] {logging_mixin.py:137} INFO - (1) - Retificado resultado preliminar para cursos superiores
[2023-02-20T21:01:15.559+0000] {logging_mixin.py:137} INFO - (2) - Divulgado edital para seleção de bolsistas do curso de Pedagogia EAD
[2023-02-20T21:01:55.162+0000] {logging_mixin.py:137} INFO - (3) - Divulgado edital IF Mais Empreendedor
[2023-02-20T21:02:39.973+0000] {logging_mixin.py:137} INFO - (4) - Prorrogadas inscrições para mestrados e doutorado
[2023-02-20T21:10:17.724+0000] {logging_mixin.py:137} INFO - ----- Exception raised: TimeoutException -----
[2023-02-20T21:10:17.832+0000] {python.py:177} INFO - Done. Returned value was: None
[2023-02-20T21:09:57.479+0000] {base_job.py:243} ERROR - LocalTaskJob heartbeat got an exception
Traceback (most recent call last):
  File "/home/airflow/.local/lib/python3.7/site-packages/sqlalchemy/engine/base.py", line 3361, in _wrap_pool_connect
    return fn()
  File "/home/airflow/.local/lib/python3.7/site-packages/sqlalchemy/pool/base.py", line 327, in connect
    return _ConnectionFairy._checkout(self)
  File "/home/airflow/.local/lib/python3.7/site-packages/sqlalchemy/pool/base.py", line 894, in _checkout
    fairy = _ConnectionRecord.checkout(pool)
  File "/home/airflow/.local/lib/python3.7/site-packages/sqlalchemy/pool/base.py", line 493, in checkout
    rec = pool._do_get()
  File "/home/airflow/.local/lib/python3.7/site-packages/sqlalchemy/pool/impl.py", line 256, in _do_get
    return self._create_connection()
  File "/home/airflow/.local/lib/python3.7/site-packages/sqlalchemy/pool/base.py", line 273, in _create_connection
    return _ConnectionRecord(self)
  File "/home/airflow/.local/lib/python3.7/site-packages/sqlalchemy/pool/base.py", line 388, in __init__
    self.__connect()
  File "/home/airflow/.local/lib/python3.7/site-packages/sqlalchemy/pool/base.py", line 691, in __connect
    pool.logger.debug("Error on connect(): %s", e)
  File "/home/airflow/.local/lib/python3.7/site-packages/sqlalchemy/util/langhelpers.py", line 72, in __exit__
    with_traceback=exc_tb,
  File "/home/airflow/.local/lib/python3.7/site-packages/sqlalchemy/util/compat.py", line 211, in raise_
    raise exception
  File "/home/airflow/.local/lib/python3.7/site-packages/sqlalchemy/pool/base.py", line 686, in __connect
    self.dbapi_connection = connection = pool._invoke_creator(self)
  File "/home/airflow/.local/lib/python3.7/site-packages/sqlalchemy/engine/create.py", line 578, in connect
    return dialect.connect(*cargs, **cparams)
  File "/home/airflow/.local/lib/python3.7/site-packages/sqlalchemy/engine/default.py", line 598, in connect
    return self.dbapi.connect(*cargs, **cparams)
  File "/home/airflow/.local/lib/python3.7/site-packages/psycopg2/__init__.py", line 122, in connect
    conn = _connect(dsn, connection_factory=connection_factory, **kwasync)
psycopg2.OperationalError: could not translate host name "postgres" to address: Temporary failure in name resolution


The above exception was the direct cause of the following exception:

Traceback (most recent call last):
  File "/home/airflow/.local/lib/python3.7/site-packages/airflow/jobs/base_job.py", line 233, in heartbeat
    session.merge(self)
  File "/home/airflow/.local/lib/python3.7/site-packages/sqlalchemy/orm/session.py", line 3057, in merge
    _resolve_conflict_map=_resolve_conflict_map,
  File "/home/airflow/.local/lib/python3.7/site-packages/sqlalchemy/orm/session.py", line 3135, in _merge
    options=options,
  File "/home/airflow/.local/lib/python3.7/site-packages/sqlalchemy/orm/session.py", line 2856, in get
    execution_options=execution_options,
  File "/home/airflow/.local/lib/python3.7/site-packages/sqlalchemy/orm/session.py", line 2974, in _get_impl
    load_options=load_options,
  File "/home/airflow/.local/lib/python3.7/site-packages/sqlalchemy/orm/loading.py", line 534, in load_on_pk_identity
    bind_arguments=bind_arguments,
  File "/home/airflow/.local/lib/python3.7/site-packages/sqlalchemy/orm/session.py", line 1713, in execute
    conn = self._connection_for_bind(bind)
  File "/home/airflow/.local/lib/python3.7/site-packages/sqlalchemy/orm/session.py", line 1553, in _connection_for_bind
    engine, execution_options
  File "/home/airflow/.local/lib/python3.7/site-packages/sqlalchemy/orm/session.py", line 747, in _connection_for_bind
    conn = bind.connect()
  File "/home/airflow/.local/lib/python3.7/site-packages/sqlalchemy/engine/base.py", line 3315, in connect
    return self._connection_cls(self, close_with_result=close_with_result)
  File "/home/airflow/.local/lib/python3.7/site-packages/sqlalchemy/engine/base.py", line 96, in __init__
    else engine.raw_connection()
  File "/home/airflow/.local/lib/python3.7/site-packages/sqlalchemy/engine/base.py", line 3394, in raw_connection
    return self._wrap_pool_connect(self.pool.connect, _connection)
  File "/home/airflow/.local/lib/python3.7/site-packages/sqlalchemy/engine/base.py", line 3365, in _wrap_pool_connect
    e, dialect, self
  File "/home/airflow/.local/lib/python3.7/site-packages/sqlalchemy/engine/base.py", line 2199, in _handle_dbapi_exception_noconnection
    sqlalchemy_exception, with_traceback=exc_info[2], from_=e
  File "/home/airflow/.local/lib/python3.7/site-packages/sqlalchemy/util/compat.py", line 211, in raise_
    raise exception
  File "/home/airflow/.local/lib/python3.7/site-packages/sqlalchemy/engine/base.py", line 3361, in _wrap_pool_connect
    return fn()
  File "/home/airflow/.local/lib/python3.7/site-packages/sqlalchemy/pool/base.py", line 327, in connect
    return _ConnectionFairy._checkout(self)
  File "/home/airflow/.local/lib/python3.7/site-packages/sqlalchemy/pool/base.py", line 894, in _checkout
    fairy = _ConnectionRecord.checkout(pool)
  File "/home/airflow/.local/lib/python3.7/site-packages/sqlalchemy/pool/base.py", line 493, in checkout
    rec = pool._do_get()
  File "/home/airflow/.local/lib/python3.7/site-packages/sqlalchemy/pool/impl.py", line 256, in _do_get
    return self._create_connection()
  File "/home/airflow/.local/lib/python3.7/site-packages/sqlalchemy/pool/base.py", line 273, in _create_connection
    return _ConnectionRecord(self)
  File "/home/airflow/.local/lib/python3.7/site-packages/sqlalchemy/pool/base.py", line 388, in __init__
    self.__connect()
  File "/home/airflow/.local/lib/python3.7/site-packages/sqlalchemy/pool/base.py", line 691, in __connect
    pool.logger.debug("Error on connect(): %s", e)
  File "/home/airflow/.local/lib/python3.7/site-packages/sqlalchemy/util/langhelpers.py", line 72, in __exit__
    with_traceback=exc_tb,
  File "/home/airflow/.local/lib/python3.7/site-packages/sqlalchemy/util/compat.py", line 211, in raise_
    raise exception
  File "/home/airflow/.local/lib/python3.7/site-packages/sqlalchemy/pool/base.py", line 686, in __connect
    self.dbapi_connection = connection = pool._invoke_creator(self)
  File "/home/airflow/.local/lib/python3.7/site-packages/sqlalchemy/engine/create.py", line 578, in connect
    return dialect.connect(*cargs, **cparams)
  File "/home/airflow/.local/lib/python3.7/site-packages/sqlalchemy/engine/default.py", line 598, in connect
    return self.dbapi.connect(*cargs, **cparams)
  File "/home/airflow/.local/lib/python3.7/site-packages/psycopg2/__init__.py", line 122, in connect
    conn = _connect(dsn, connection_factory=connection_factory, **kwasync)
sqlalchemy.exc.OperationalError: (psycopg2.OperationalError) could not translate host name "postgres" to address: Temporary failure in name resolution

(Background on this error at: https://sqlalche.me/e/14/e3q8)
[2023-02-20T21:12:05.498+0000] {local_task_job.py:192} ERROR - Heartbeat time limit exceeded!
[2023-02-20T21:12:05.998+0000] {process_utils.py:133} INFO - Sending Signals.SIGTERM to group 3362. PIDs of all processes in the group: [3362]
[2023-02-20T21:12:06.013+0000] {process_utils.py:84} INFO - Sending the signal Signals.SIGTERM to group 3362
[2023-02-20T21:12:09.546+0000] {taskinstance.py:1479} ERROR - Received SIGTERM. Terminating subprocesses.
[2023-02-20T21:12:11.249+0000] {taskinstance.py:1768} ERROR - Task failed with exception
Traceback (most recent call last):
  File "/home/airflow/.local/lib/python3.7/site-packages/airflow/models/taskinstance.py", line 1376, in _run_raw_task
    self.refresh_from_db(lock_for_update=True, session=session)
  File "/home/airflow/.local/lib/python3.7/site-packages/airflow/utils/session.py", line 72, in wrapper
    return func(*args, **kwargs)
  File "/home/airflow/.local/lib/python3.7/site-packages/airflow/models/taskinstance.py", line 787, in refresh_from_db
    for attempt in run_with_db_retries(logger=self.log):
  File "/home/airflow/.local/lib/python3.7/site-packages/tenacity/__init__.py", line 384, in __iter__
    do = self.iter(retry_state=retry_state)
  File "/home/airflow/.local/lib/python3.7/site-packages/tenacity/__init__.py", line 351, in iter
    return fut.result()
  File "/usr/local/lib/python3.7/concurrent/futures/_base.py", line 428, in result
    return self.__get_result()
  File "/usr/local/lib/python3.7/concurrent/futures/_base.py", line 384, in __get_result
    raise self._exception
  File "/home/airflow/.local/lib/python3.7/site-packages/airflow/models/taskinstance.py", line 789, in refresh_from_db
    ti: TaskInstance | None = qry.with_for_update().one_or_none()
  File "/home/airflow/.local/lib/python3.7/site-packages/sqlalchemy/orm/query.py", line 2850, in one_or_none
    return self._iter().one_or_none()
  File "/home/airflow/.local/lib/python3.7/site-packages/sqlalchemy/orm/query.py", line 2919, in _iter
    execution_options={"_sa_orm_load_options": self.load_options},
  File "/home/airflow/.local/lib/python3.7/site-packages/sqlalchemy/orm/session.py", line 1713, in execute
    conn = self._connection_for_bind(bind)
  File "/home/airflow/.local/lib/python3.7/site-packages/sqlalchemy/orm/session.py", line 1553, in _connection_for_bind
    engine, execution_options
  File "/home/airflow/.local/lib/python3.7/site-packages/sqlalchemy/orm/session.py", line 747, in _connection_for_bind
    conn = bind.connect()
  File "/home/airflow/.local/lib/python3.7/site-packages/sqlalchemy/engine/base.py", line 3315, in connect
    return self._connection_cls(self, close_with_result=close_with_result)
  File "/home/airflow/.local/lib/python3.7/site-packages/sqlalchemy/engine/base.py", line 96, in __init__
    else engine.raw_connection()
  File "/home/airflow/.local/lib/python3.7/site-packages/sqlalchemy/engine/base.py", line 3394, in raw_connection
    return self._wrap_pool_connect(self.pool.connect, _connection)
  File "/home/airflow/.local/lib/python3.7/site-packages/sqlalchemy/engine/base.py", line 3361, in _wrap_pool_connect
    return fn()
  File "/home/airflow/.local/lib/python3.7/site-packages/sqlalchemy/pool/base.py", line 327, in connect
    return _ConnectionFairy._checkout(self)
  File "/home/airflow/.local/lib/python3.7/site-packages/sqlalchemy/pool/base.py", line 894, in _checkout
    fairy = _ConnectionRecord.checkout(pool)
  File "/home/airflow/.local/lib/python3.7/site-packages/sqlalchemy/pool/base.py", line 493, in checkout
    rec = pool._do_get()
  File "/home/airflow/.local/lib/python3.7/site-packages/sqlalchemy/pool/impl.py", line 256, in _do_get
    return self._create_connection()
  File "/home/airflow/.local/lib/python3.7/site-packages/sqlalchemy/pool/base.py", line 273, in _create_connection
    return _ConnectionRecord(self)
  File "/home/airflow/.local/lib/python3.7/site-packages/sqlalchemy/pool/base.py", line 388, in __init__
    self.__connect()
  File "/home/airflow/.local/lib/python3.7/site-packages/sqlalchemy/pool/base.py", line 691, in __connect
    pool.logger.debug("Error on connect(): %s", e)
  File "/home/airflow/.local/lib/python3.7/site-packages/sqlalchemy/util/langhelpers.py", line 72, in __exit__
    with_traceback=exc_tb,
  File "/home/airflow/.local/lib/python3.7/site-packages/sqlalchemy/util/compat.py", line 211, in raise_
    raise exception
  File "/home/airflow/.local/lib/python3.7/site-packages/sqlalchemy/pool/base.py", line 686, in __connect
    self.dbapi_connection = connection = pool._invoke_creator(self)
  File "/home/airflow/.local/lib/python3.7/site-packages/sqlalchemy/engine/create.py", line 578, in connect
    return dialect.connect(*cargs, **cparams)
  File "/home/airflow/.local/lib/python3.7/site-packages/sqlalchemy/engine/default.py", line 598, in connect
    return self.dbapi.connect(*cargs, **cparams)
  File "/home/airflow/.local/lib/python3.7/site-packages/psycopg2/__init__.py", line 122, in connect
    conn = _connect(dsn, connection_factory=connection_factory, **kwasync)
  File "/home/airflow/.local/lib/python3.7/site-packages/airflow/models/taskinstance.py", line 1481, in signal_handler
    raise AirflowException("Task received SIGTERM signal")
airflow.exceptions.AirflowException: Task received SIGTERM signal
[2023-02-20T21:12:11.585+0000] {taskinstance.py:1323} INFO - Marking task as UP_FOR_RETRY. dag_id=ifgoiano_site_dag, task_id=get_data, execution_date=20230219T210000, start_date=20230220T210008, end_date=20230220T211211
[2023-02-20T21:12:11.980+0000] {standard_task_runner.py:105} ERROR - Failed to execute job 18 for task get_data (Task received SIGTERM signal; 3362)
[2023-02-20T21:12:12.469+0000] {process_utils.py:79} INFO - Process psutil.Process(pid=3362, status='terminated', exitcode=1, started='21:00:07') (3362) terminated with exit code 1
[2023-02-20T23:05:54.431+0000] {taskinstance.py:1083} INFO - Dependencies all met for <TaskInstance: ifgoiano_site_dag.get_data scheduled__2023-02-19T21:00:00+00:00 [queued]>
[2023-02-20T23:05:54.565+0000] {taskinstance.py:1083} INFO - Dependencies all met for <TaskInstance: ifgoiano_site_dag.get_data scheduled__2023-02-19T21:00:00+00:00 [queued]>
[2023-02-20T23:05:54.566+0000] {taskinstance.py:1279} INFO - 
--------------------------------------------------------------------------------
[2023-02-20T23:05:54.570+0000] {taskinstance.py:1280} INFO - Starting attempt 1 of 6
[2023-02-20T23:05:54.570+0000] {taskinstance.py:1281} INFO - 
--------------------------------------------------------------------------------
[2023-02-20T23:05:54.665+0000] {taskinstance.py:1300} INFO - Executing <Task(PythonOperator): get_data> on 2023-02-19 21:00:00+00:00
[2023-02-20T23:05:54.679+0000] {standard_task_runner.py:55} INFO - Started process 1325 to run task
[2023-02-20T23:05:54.692+0000] {standard_task_runner.py:82} INFO - Running: ['***', 'tasks', 'run', 'ifgoiano_site_dag', 'get_data', 'scheduled__2023-02-19T21:00:00+00:00', '--job-id', '26', '--raw', '--subdir', 'DAGS_FOLDER/ifgoiano_site_dag.py', '--cfg-path', '/tmp/tmpuyuijb4b']
[2023-02-20T23:05:54.701+0000] {standard_task_runner.py:83} INFO - Job 26: Subtask get_data
[2023-02-20T23:05:55.149+0000] {task_command.py:388} INFO - Running <TaskInstance: ifgoiano_site_dag.get_data scheduled__2023-02-19T21:00:00+00:00 [running]> on host e08066d9c5e1
[2023-02-20T23:05:55.669+0000] {taskinstance.py:1509} INFO - Exporting the following env vars:
AIRFLOW_CTX_DAG_OWNER=Rafael
AIRFLOW_CTX_DAG_ID=ifgoiano_site_dag
AIRFLOW_CTX_TASK_ID=get_data
AIRFLOW_CTX_EXECUTION_DATE=2023-02-19T21:00:00+00:00
AIRFLOW_CTX_TRY_NUMBER=1
AIRFLOW_CTX_DAG_RUN_ID=scheduled__2023-02-19T21:00:00+00:00
[2023-02-20T23:05:55.683+0000] {logging_mixin.py:137} INFO - ----- Bot is running -----
[2023-02-20T23:06:21.084+0000] {logging_mixin.py:137} INFO - (1) - Retificado resultado preliminar para cursos superiores
[2023-02-20T23:06:44.547+0000] {logging_mixin.py:137} INFO - (2) - Divulgado edital para seleção de bolsistas do curso de Pedagogia EAD
[2023-02-20T23:07:07.945+0000] {logging_mixin.py:137} INFO - (3) - Divulgado edital IF Mais Empreendedor
[2023-02-20T23:07:31.279+0000] {logging_mixin.py:137} INFO - (4) - Prorrogadas inscrições para mestrados e doutorado
[2023-02-20T23:14:00.691+0000] {logging_mixin.py:137} INFO - ----- Exception raised: TimeoutException -----
[2023-02-20T23:14:00.910+0000] {python.py:177} INFO - Done. Returned value was: None
[2023-02-20T23:14:06.467+0000] {taskinstance.py:1323} INFO - Marking task as SUCCESS. dag_id=ifgoiano_site_dag, task_id=get_data, execution_date=20230219T210000, start_date=20230220T230554, end_date=20230220T231406
[2023-02-20T23:14:39.643+0000] {local_task_job.py:208} INFO - Task exited with return code 0
[2023-02-20T23:14:40.610+0000] {taskinstance.py:2578} INFO - 0 downstream tasks scheduled from follow-on schedule check
